Workbook

Sheet Home
A1: ⌂ HOME | D1: ▥ HEALTH OVERVIEW | H1: 💡 INSIGHTS | K1: ? BUSINESS QUESTIONS | N1: ▣ DATA DICTIONARY | Q1: ▤ ANALYSIS | S1: ▦ RAW DATA
A3: MEDISIGHTS
A4: MEDISIGHTS HEALTH INTELLIGENCE HUB
A8: DATA-DRIVEN CLINICAL INSIGHTS • POPULATION HEALTH ANALYTICS • EXCEL BI DASHBOARD
A9: Data as of 5/22/2025 | 4,155 records | 20 analytical fields
A10: DATASET OVERVIEW
A11: EXECUTIVE SNAPSHOT
A12: POPULATION | F12: AVERAGE AGE | K12: AVERAGE BMI | P12: AVERAGE SBP
A13: 4,155 | F13: 53.30 | K13: 27.03 | P13: 109.01
A15: Records | F15: Years | K15: kg/m² | P15: mmHg
A16: AVERAGE DBP | F16: AVERAGE CHOLESTEROL | K16: SMOKING RATE | P16: OVERWEIGHT + OBESE
A17: 81.80 | F17: 193.19 | K17: 26.14% | P17: 56.15%
A19: mmHg | F19: mg/dL | K19: Smokers | P19: Population
A20: KEY POPULATION SIGNALS
A21: BMI | F21: BLOOD PRESSURE | K21: SMOKING | P21: CHOLESTEROL
A22: Average BMI is 27.03 kg/m² Focus on weight-risk segmentation. | F22: Average SBP / DBP = 109.01 / 81.80 Use BP category distribution for risk review. | K22: 26.14% of the population are smokers Compare smoking status with BMI and BP. | P22: Average total cholesterol = 193.19 mg/dL Review desirable / borderline / high categories.
A26: DASHBOARD NAVIGATION
A27: HEALTH OVERVIEW | G27: INSIGHTS | M27: BUSINESS QUESTIONS
A28: 12 interactive charts + population KPIs | G28: Analytical findings and patterns | M28: Decision-oriented questions
A30: DATA DICTIONARY | G30: ANALYSIS | M30: RAW DATA
A31: Definitions of fields and metrics | G31: Supporting calculations | M31: Underlying population records
A33: 1 Open HEALTH OVERVIEW for the population KPI snapshot.
A34: 2 Use the dropdown filters to focus on smoking, activity, BMI, age, cholesterol or blood pressure.
A35: 3 Review the 12 charts; values are based on the current Raw Data.
A36: MEDISIGHTS | Clinical intelligence through structured population-level analytics
A38: How to use: Start with HEALTH OVERVIEW → apply the available filters → review the 12 charts → move to INSIGHTS and BUSINESS QUESTIONS for interpretation. The workbook does not contain a Gender/Sex source field, so gender-based results are not fabricated.
A43: RISK SUMMARY | G43: DATA QUALITY | M43: INSIGHTS

Sheet Risk Summary
A1: POPULATION RISK SUMMARY
A3: Executive risk view • analytical segmentation only, not clinical diagnosis
A5: EXECUTIVE RISK INDICATORS
A6: Indicator | B6: People | C6: % Population | D6: Signal
A7: Smokers | B7: =COUNTIF('Raw Data'!I2:I4156,"Smoker") -> 1235 | C7: =B7/4155 -> 0.29723225 | D7: =IF(C7>=0.5,"HIGH",IF(C7>=0.25,"MODERATE","LOW")) -> MODERATE
A8: Overweight + Obese | B8: =COUNTIF('Raw Data'!B2:B4156,">=25") -> 2733 | C8: =B8/4155 -> 0.65776173 | D8: =IF(C8>=0.5,"HIGH",IF(C8>=0.25,"MODERATE","LOW")) -> HIGH
A9: Low HDL | B9: =COUNTIF('Raw Data'!F2:F4156,"<40") -> 2967 | C9: =B9/4155 -> 0.71407942 | D9: =IF(C9>=0.5,"HIGH",IF(C9>=0.25,"MODERATE","LOW")) -> HIGH
A10: SBP ≥ 130 | B10: =COUNTIF('Raw Data'!C2:C4156,">=130") -> 81 | C10: =B10/4155 -> 0.019494585 | D10: =IF(C10>=0.5,"HIGH",IF(C10>=0.25,"MODERATE","LOW")) -> LOW
A11: Cholesterol ≥ 240 | B11: =COUNTIF('Raw Data'!E2:E4156,">=240") -> 11 | C11: =B11/4155 -> 0.0026474128 | D11: =IF(C11>=0.5,"HIGH",IF(C11>=0.25,"MODERATE","LOW")) -> LOW
A14: ANALYTICAL POPULATION RISK SCORE
A15: One point for each: BMI ≥25, SBP ≥130, cholesterol ≥240, low HDL, and smoking. This is an analytical prioritization aid, not a clinical diagnosis.
A18: Component | B18: Population % | C18: Points
A19: BMI ≥25 | B19: =C8 -> 0.65776173 | C19: 1
A20: SBP ≥130 | B20: =C10 -> 0.019494585 | C20: 1
A21: Cholesterol ≥240 | B21: =C11 -> 0.0026474128 | C21: 1
A22: Low HDL | B22: =C9 -> 0.71407942 | C22: 1
A23: Smoker | B23: =C7 -> 0.29723225 | C23: 1
A25: Population Risk Index | B25: =SUMPRODUCT(B19:B23,C19:C23)/5 -> 0.33824308 | C25: =IF(B25>=0.5,"HIGH",IF(B25>=0.25,"MODERATE","LOW")) -> MODERATE
A27: HOME | B27: HEALTH OVERVIEW | C27: RISK SUMMARY | D27: INSIGHTS | E27: DATA QUALITY | F27: ANALYSIS

Sheet Health Overview Dashboard
A1: HEALTH OVERVIEW DASHBOARD | R1: Data as of: 5/22/2025
A2: Overall Population Health Profile
A3: HOME | D3: HEALTH OVERVIEW | H3: INSIGHTS | K3: BUSINESS QUESTIONS | N3: DATA DICTIONARY | Q3: ANALYSIS | S3: RAW DATA
A4: FILTERS ▼ | D4: Total Number of People | G4: Average BMI (kg/m²) | J4: Average Systolic BP (mmHg) | M4: Average Diastolic BP (mmHg) | P4: Average Total Cholesterol (mg/dL)
A6: Gender | D6: 4,155 | G6: 27.03 | J6: 109.01 | M6: 81.80 | P6: 193.19
A7: Not available | D7: Average Age (Years) | G7: Smoking Rate (% Smokers) | J7: Overweight + Obese (% of Population) | M7: Low HDL (% of Population) | P7: Population with SBP ≥130 (% of Population)
A9: Smoking Status | D9: 53.30% | G9: 29.72% | J9: 66.40% | M9: 71.41% | P9: 1.95%
A10: (All)
D11: 1. SMOKING STATUS | H11: 2. PHYSICAL ACTIVITY LEVEL | L11: 3. BMI CATEGORY DISTRIBUTION | P11: 4. BMI % DISTRIBUTION
A12: Physical Activity Level
A13: (All)
A15: BMI Category
A16: (All)
A18: Age Group
A19: (All)
A20: ↻ RESET FILTERS | D20: 5. TOTAL CHOLESTEROL CATEGORY | H20: 6. SYSTOLIC BP CATEGORY | L20: 7. AGE GROUP DISTRIBUTION | P20: 8. AVERAGE BMI BY ACTIVITY LEVEL
A22: (All)
A24: Systolic BP Category
A25: (All)
D29: 9. AVERAGE BMI BY SMOKING STATUS | H29: 10. AVERAGE SYSTOLIC BP BY AGE GROUP | L29: 11. BMI CATEGORY BY PHYSICAL ACTIVITY (%) | P29: 12. PHYSICAL ACTIVITY BY BMI CATEGORY (%)

Sheet Business Questions
A1: HOME | C1: HEALTH OVERVIEW | E1: INSIGHTS | G1: BUSINESS QUESTIONS | I1: DATA DICTIONARY | K1: ANALYSIS | M1: RAW DATA
A3: BUSINESS QUESTIONS
A5: # | B5: Difficulty | D5: Business Question | J5: Result | O5: Interpretation
A6: 1 | B6: Easy | D6: How many people are included in the dataset? | J6: =Analysis!$C$4203 -> 0 | O6: Total valid records analyzed in the current filter view.
A7: 2 | B7: Easy | D7: How many people are smokers vs non-smokers? | J7: ="Smokers: "&TEXT(Analysis!$F$4204,"#,##0")&" | Non-Smokers: "&TEXT(Analysis!$F$4205,"#,##0") -> Smokers: 0 | Non-Smokers: 0 | O7: Shows the balance of smoking behavior across the selected population.
A8: 3 | B8: Easy | D8: How many people belong to each physical activity level? | J8: ="Low: "&Analysis!$I$4204&" | Moderate: "&Analysis!$I$4205&" | High: "&Analysis!$I$4206 -> Low: 0 | Moderate: 0 | High: 0 | O8: Physical activity segmentation supports lifestyle-risk analysis.
A9: 4 | B9: Medium | D9: How are people distributed across BMI categories? | J9: ="UW: "&Analysis!$L$4204&" | Normal: "&Analysis!$L$4205&" | OW: "&Analysis!$L$4206&" | Obese: "&Analysis!$L$4207 -> UW: 0 | Normal: 0 | OW: 0 | Obese: 0 | O9: Underweight, Normal, Overweight and Obese counts (standard BMI thresholds).
A10: 5 | B10: Medium | D10: How many people have desirable / borderline high / high total cholesterol? | J10: ="Desirable: "&Analysis!$R$4204&" | Borderline: "&Analysis!$R$4205&" | High: "&Analysis!$R$4206 -> Desirable: 0 | Borderline: 0 | High: 0 | O10: Cholesterol classification follows standard clinical reference bands (<200 / 200-239 / ≥240).
A11: 6 | B11: Medium | D11: How many people have normal / elevated / Stage 1 / Stage 2 systolic BP? | J11: ="Normal: "&Analysis!$U$4204&" | Elevated: "&Analysis!$U$4205&" | Stage1: "&Analysis!$U$4206&" | Stage2: "&Analysis!$U$4207 -> Normal: 0 | Elevated: 0 | Stage1: 0 | Stage2: 0 | O11: Systolic BP classification (<120 / 120-129 / 130-139 / ≥140).
A12: 7 | B12: Hard | D12: What percentage of the population falls into each BMI category? | J12: =TEXT(Analysis!$N$4204,"0.0%")&" UW | "&TEXT(Analysis!$N$4205,"0.0%")&" Normal | "&TEXT(Analysis!$N$4206,"0.0%")&" OW | "&TEXT(Analysis!$N$4207,"0.0%")&" Obese" -> 18-29 UW | 30-39 Normal | 40-49 OW | 50-59 Obese | O12: Percentage share of the filtered population per BMI category.
A13: 8 | B13: Medium | D13: Which age group represents the largest share of the population? | J13: =Analysis!$C$4237 -> 18-29 | O13: The age group with the highest record count.
A14: 9 | B14: Medium | D14: What percentage of the population has systolic BP ≥ 130? | J14: =Analysis!$C$4212 -> 0 | O14: Combined High/Stage 1 + Stage 2 share of the population.
A15: 10 | B15: Medium | D15: What percentage of the population has HDL below 40 mg/dL? | J15: =Analysis!$C$4211 -> 0 | O15: Low HDL is an established cardiovascular risk marker.
A16: 11 | B16: Easy | D16: Which physical activity level is most common? | J16: =Analysis!$C$4238 -> low | O16: The activity level with the highest record count.
A17: 12 | B17: Hard | D17: How does average BMI differ between smokers and non-smokers? | J17: ="Smokers: "&TEXT(Analysis!$B$4214,"0.00")&" | Non-Smokers: "&TEXT(Analysis!$B$4215,"0.00") -> Smokers: 0.00 | Non-Smokers: 0.00 | O17: Compares average BMI across smoking status.
A18: 13 | B18: Advanced | D18: How does BMI category distribution relate to physical activity level? | J18: See 'Physical Activity by BMI Category' chart, Health Overview page. | O18: Cross-tabulation of activity level against BMI category.
A19: 14 | B19: Advanced | D19: How does cholesterol classification vary across BMI categories? | J19: See 'Cholesterol Category by BMI Category' chart, Health Overview page. | O19: Cross-tabulation of cholesterol classification against BMI category.
A20: 15 | B20: Hard | D20: Which age group has the highest average systolic blood pressure? | J20: =Analysis!$C$4240 -> 18-29 | O20: Identifies the age segment with the highest average SBP.
A21: 16 | B21: Hard | D21: Which BMI category has the highest average total cholesterol? | J21: =Analysis!$C$4239 -> Underweight | O21: Identifies which BMI category carries the highest average cholesterol.
A22: 17 | B22: Hard | D22: Which age group has the highest average total cholesterol? | J22: =Analysis!$C$4241 -> 18-29 | O22: Identifies the age segment with the highest average cholesterol.
A23: 18 | B23: Hard | D23: Which activity group has the highest average BMI? | J23: =Analysis!$C$4242 -> INSIGHTS | O23: Identifies which activity level carries the highest average BMI.
A24: 19 | B24: Advanced | D24: What percentage of the population is simultaneously Overweight/Obese, has Low HDL, and SBP ≥ 130? | J24: =Analysis!$C$4213 -> 0 | O24: A compounded, higher-risk lifestyle segment worth prioritizing for outreach.
A25: 20 | B25: Medium | D25: What is the overall smoking rate in the population? | J25: =Analysis!$C$4209 -> 0 | O25: Share of the population currently classified as smokers.
A26: 21 | B26: Medium | D26: What share of the population is Overweight or Obese? | J26: =Analysis!$C$4210 -> 0 | O26: Combined Overweight + Obese share of the population.
A27: 22 | B27: Advanced | D27: How is the population distributed across the MEDISIGHTS analytical health-risk tiers? | J27: See 'Analytical Health Risk Tier' chart, Health Overview page. | O27: An internally-defined composite index (BMI + SBP + smoking + HDL) — for population segmentation only, not a clinical score.
A29: DYNAMIC BUSINESS ANSWERS
A30: Largest risk segment | B30: Overweight + Obese | C30: ='Risk Summary'!C8 -> 0.65776173
A31: Smoking prevalence | B31: Smokers | C31: ='Risk Summary'!C7 -> 0.29723225
A32: SBP ≥130 prevalence | B32: SBP ≥130 | C32: ='Risk Summary'!C10 -> 0.019494585
A33: Low HDL prevalence | B33: Low HDL | C33: ='Risk Summary'!C9 -> 0.71407942

Sheet Data Dictionary
A1: HOME | C1: HEALTH OVERVIEW | E1: INSIGHTS | G1: BUSINESS QUESTIONS | I1: DATA DICTIONARY | K1: ANALYSIS | M1: RAW DATA
A3: DATA DICTIONARY
A5: Column Name | D5: Data Type | F5: Business Meaning | J5: Description | O5: Unit | P5: Example Value | R5: Used In | T5: Derived?
A6: Age | D6: Numeric (years) | F6: Patient age | J6: Age of the individual in completed years. | O6: years | P6: 69 | R6: KPIs, Age Group, all age cross-tabs | T6: No
A7: BMI | D7: Numeric | F7: Body Mass Index | J7: Weight-to-height ratio used to classify body composition. | O7: kg/m² | P7: 20.72 | R7: KPIs, BMI Category, most charts | T7: No
A8: Systolic_BP | D8: Numeric | F8: Systolic blood pressure | J8: Pressure in arteries during heartbeats. | O8: mmHg | P8: 107.1 | R8: KPIs, SBP Category, BP charts | T8: No
A9: Diastolic_BP | D9: Numeric | F9: Diastolic blood pressure | J9: Pressure in arteries between heartbeats. | O9: mmHg | P9: 58.3 | R9: KPI card | T9: No
A10: Total_Cholesterol | D10: Numeric | F10: Total cholesterol | J10: Combined HDL + LDL + a portion of triglycerides. | O10: mg/dL | P10: 168.9 | R10: KPIs, Cholesterol Category, charts | T10: No
A11: HDL_Cholesterol | D11: Numeric | F11: 'Good' cholesterol | J11: High-density lipoprotein cholesterol. | O11: mg/dL | P11: 38.4 | R11: Low HDL KPI, HDL Distribution chart | T11: No
A12: LDL_Cholesterol | D12: Numeric | F12: 'Bad' cholesterol | J12: Low-density lipoprotein cholesterol. | O12: mg/dL | P12: 183.8 | R12: Raw Data reference | T12: No
A13: Triglycerides | D13: Numeric | F13: Blood fat level | J13: Triglyceride concentration in blood. | O13: mg/dL | P13: 243.3 | R13: Raw Data reference | T13: No
A14: Smoking_Status | D14: Text | F14: Smoking behavior | J14: Whether the individual currently smokes. | O14: smoker / non-smoker | P14: non-smoker | R14: Filters, KPIs, all smoking charts | T14: No
A15: Physical_Activity_Level | D15: Text | F15: Activity level | J15: Self-reported level of physical activity. | O15: low / moderate / high | P15: moderate | R15: Filters, KPIs, activity charts | T15: No
A16: BP_Risk_Category | D16: Text | F16: Simple BP risk flag | J16: Binary blood-pressure risk classification from the source data. | O16: Normal / Elevated-High Risk | P16: Normal | R16: Reference only | T16: No
... A25: Risk_Tier (Analytical) | D25: Text (formula) | F25: Risk tier label | J25: Health_Risk_Score bucketed into Low (0-2) / Moderate (3-5) / High (6-9). NOT a clinical diagnosis. | O25: Low/Moderate/High | P25: Moderate | R25: Risk Tier chart, Insights | T25: Yes
A27: 'Derived = Yes' columns are calculated with live formulas from the original raw fields and are clearly separated at the end of the Raw Data table (columns Q–T).

Sheet Analysis
A1: ANALYSIS — CALCULATION LAYER
A2: All values below are formula-driven and update automatically when Raw Data changes.
A4: ID | B4: BMI | C4: BMI Category | D4: Total Cholesterol | E4: Cholesterol Classification | F4: Systolic BP | G4: Systolic BP Classification | H4: Smoking Status | I4: Physical Activity Level | K4: KPI CALCULATIONS
A5: =ROW()-4 -> 1 | B5: ='Raw Data'!B2 -> 20.716059 | C5: =IF(B5<18.5,"Underweight",IF(B5<=24.9,"Normal",IF(B5<=29.9,"Overweight","Obese"))) -> Normal | D5: ='Raw Data'!E2 -> 168.91851 | E5: =IF(D5<200,"Desirable",IF(D5<=239,"Borderline High","High")) -> Desirable | F5: ='Raw Data'!C2 -> 107.14844 | G5: =IF(F5<120,"Normal",IF(F5<=129,"Elevated",IF(F5<=139,"Stage 1 Hypertension","Stage 2 Hypertension"))) -> Normal | H5: ='Raw Data'!I2 -> non-smoker | I5: ='Raw Data'!J2 -> moderate | K5: Metric | L5: Value
A6: =ROW()-4 -> 2 | B6: ='Raw Data'!B3 -> 26.720231 | C6: =IF(B6<18.5,"Underweight",IF(B6<=24.9,"Normal",IF(B6<=29.9,"Overweight","Obese"))) -> Overweight | D6: ='Raw Data'!E3 -> 203.91201 | E6: =IF(D6<200,"Desirable",IF(D6<=239,"Borderline High","High")) -> Borderline High | F6: ='Raw Data'!C3 -> 102.94833 | G6: =IF(F6<120,"Normal",IF(F6<=129,"Elevated",IF(F6<=139,"Stage 1 Hypertension","Stage 2 Hypertension"))) -> Normal | H6: ='Raw Data'!I3 -> smoker | I6: ='Raw Data'!J3 -> high | K6: Total Number of People | L6: =COUNTA('Raw Data'!A2:A4156) -> 4155
A7: =ROW()-4 -> 3 | B7: ='Raw Data'!B4 -> 25.971636 | C7: =IF(B7<18.5,"Underweight",IF(B7<=24.9,"Normal",IF(B7<=29.9,"Overweight","Obese"))) -> Overweight | D7: ='Raw Data'!E4 -> 213.56482 | E7: =IF(D7<200,"Desirable",IF(D7<=239,"Borderline High","High")) -> Borderline High | F7: ='Raw Data'!C4 -> 116.32703 | G7: =IF(F7<120,"Normal",IF(F7<=129,"Elevated",IF(F7<=139,"Stage 1 Hypertension","Stage 2 Hypertension"))) -> Normal | H7: ='Raw Data'!I4 -> non-smoker | I7: ='Raw Data'!J4 -> moderate | K7: Average BMI | L7: =AVERAGE('Raw Data'!B2:B4156) -> 27.0258
A8: =ROW()-4 -> 4 | B8: ='Raw Data'!B5 -> 29.580788 | C8: =IF(B8<18.5,"Underweight",IF(B8<=24.9,"Normal",IF(B8<=29.9,"Overweight","Obese"))) -> Overweight | D8: ='Raw Data'!E5 -> 204.30191 | E8: =IF(D8<200,"Desirable",IF(D8<=239,"Borderline High","High")) -> Borderline High | F8: ='Raw Data'!C5 -> 104.2738 | G8: =IF(F8<120,"Normal",IF(F8<=129,"Elevated",IF(F8<=139,"Stage 1 Hypertension","Stage 2 Hypertension"))) -> Normal | H8: ='Raw Data'!I5 -> non-smoker | I8: ='Raw Data'!J5 -> moderate | K8: Average Systolic Blood Pressure | L8: =AVERAGE('Raw Data'!C2:C4156) -> 109.0148
A9: =ROW()-4 -> 5 | B9: ='Raw Data'!B6 -> 28.35313 | C9: =IF(B9<18.5,"Underweight",IF(B9<=24.9,"Normal",IF(B9<=29.9,"Overweight","Obese"))) -> Overweight | D9: ='Raw Data'!E6 -> 195.76714 | E9: =IF(D9<200,"Desirable",IF(D9<=239,"Borderline High","High")) -> Desirable | F9: ='Raw Data'!C6 -> 104.05258 | G9: =IF(F9<120,"Normal",IF(F9<=129,"Elevated",IF(F9<=139,"Stage 1 Hypertension","Stage 2 Hypertension"))) -> Normal | H9: ='Raw Data'!I6 -> non-smoker | I9: ='Raw Data'!J6 -> moderate | K9: Average Diastolic Blood Pressure | L9: =AVERAGE('Raw Data'!D2:D4156) -> 81.800284
A10: =ROW()-4 -> 6 | B10: ='Raw Data'!B7 -> 27.996372 | C10: =IF(B10<18.5,"Underweight",IF(B10<=24.9,"Normal",IF(B10<=29.9,"Overweight","Obese"))) -> Overweight | D10: ='Raw Data'!E7 -> 209.92055 | E10: =IF(D10<200,"Desirable",IF(D10<=239,"Borderline High","High")) -> Borderline High | F10: ='Raw Data'!C7 -> 108.0406 | G10: =IF(F10<120,"Normal",IF(F10<=129,"Elevated",IF(F10<=139,"Stage 1 Hypertension","Stage 2 Hypertension"))) -> Normal | H10: ='Raw Data'!I7 -> smoker | I10: ='Raw Data'!J7 -> moderate | K10: Average Total Cholesterol | L10: =AVERAGE('Raw Data'!E2:E4156) -> 193.18813
A11: =ROW()-4 -> 7 | B11: ='Raw Data'!B8 -> 31.834551 | C11: =IF(B11<18.5,"Underweight",IF(B11<=24.9,"Normal",IF(B11<=29.9,"Overweight","Obese"))) -> Obese | D11: ='Raw Data'!E8 -> 190.26447 | E11: =IF(D11<200,"Desirable",IF(D11<=239,"Borderline High","High")) -> Desirable | F11: ='Raw Data'!C8 -> 111.37421 | G11: =IF(F11<120,"Normal",IF(F11<=129,"Elevated",IF(F11<=139,"Stage 1 Hypertension","Stage 2 Hypertension"))) -> Normal | H11: ='Raw Data'!I8 -> non-smoker | I11: ='Raw Data'!J8 -> low
A12: =ROW()-4 -> 8 | B12: ='Raw Data'!B9 -> 24.850209 | C12: =IF(B12<18.5,"Underweight",IF(B12<=24.9,"Normal",IF(B12<=29.9,"Overweight","Obese"))) -> Normal | D12: ='Raw Data'!E9 -> 173.17795 | E12: =IF(D12<200,"Desirable",IF(D12<=239,"Borderline High","High")) -> Desirable | F12: ='Raw Data'!C9 -> 101.27835 | G12: =IF(F12<120,"Normal",IF(F12<=129,"Elevated",IF(F12<=139,"Stage 1 Hypertension","Stage 2 Hypertension"))) -> Normal | H12: ='Raw Data'!I9 -> smoker | I12: ='Raw Data'!J9 -> high
A13: =ROW()-4 -> 9 | B13: ='Raw Data'!B10 -> 29.693623 | C13: =IF(B13<18.5,"Underweight",IF(B13<=24.9,"Normal",IF(B13<=29.9,"Overweight","Obese"))) -> Overweight | D13: ='Raw Data'!E10 -> 207.03529 | E13: =IF(D13<200,"Desirable",IF(D13<=239,"Borderline High","High")) -> Borderline High | F13: ='Raw Data'!C10 -> 103.89739 | G13: =IF(F13<120,"Normal",IF(F13<=129,"Elevated",IF(F13<=139,"Stage 1 Hypertension","Stage 2 Hypertension"))) -> Normal | H13: ='Raw Data'!I10 -> non-smoker | I13: ='Raw Data'!J10 -> high | K13: Q2 — SMOKING STATUS
A14: =ROW()-4 -> 10 | B14: ='Raw Data'!B11 -> 28.404333 | C14: =IF(B14<18.5,"Underweight",IF(B14<=24.9,"Normal",IF(B14<=29.9,"Overweight","Obese"))) -> Overweight | D14: ='Raw Data'!E11 -> 212.837 | E14: =IF(D14<200,"Desirable",IF(D14<=239,"Borderline High","High")) -> Borderline High | F14: ='Raw Data'!C11 -> 94.798266 | G14: =IF(F14<120,"Normal",IF(F14<=129,"Elevated",IF(F14<=139,"Stage 1 Hypertension","Stage 2 Hypertension"))) -> Normal | H14: ='Raw Data'!I11 -> non-smoker | I14: ='Raw Data'!J11 -> high | K14: Category | L14: Count | M14: Percent
A15: =ROW()-4 -> 11 | B15: ='Raw Data'!B12 -> 27.569727 | C15: =IF(B15<18.5,"Underweight",IF(B15<=24.9,"Normal",IF(B15<=29.9,"Overweight","Obese"))) -> Overweight | D15: ='Raw Data'!E12 -> 174.18979 | E15: =IF(D15<200,"Desirable",IF(D15<=239,"Borderline High","High")) -> Desirable | F15: ='Raw Data'!C12 -> 108.97669 | G15: =IF(F15<120,"Normal",IF(F15<=129,"Elevated",IF(F15<=139,"Stage 1 Hypertension","Stage 2 Hypertension"))) -> Normal | H15: ='Raw Data'!I12 -> smoker | I15: ='Raw Data'!J12 -> high | K15: Smoker | L15: =COUNTIFS(H5:H4159,"smoker") -> 1235 | M15: =L15/L6 -> 0.29723225
A16: =ROW()-4 -> 12 | B16: ='Raw Data'!B13 -> 26.671476 | C16: =IF(B16<18.5,"Underweight",IF(B16<=24.9,"Normal",IF(B16<=29.9,"Overweight","Obese"))) -> Overweight | D16: ='Raw Data'!E13 -> 176.70644 | E16: =IF(D16<200,"Desirable",IF(D16<=239,"Borderline High","High")) -> Desirable | F16: ='Raw Data'!C13 -> 104.67322 | G16: =IF(F16<120,"Normal",IF(F16<=129,"Elevated",IF(F16<=139,"Stage 1 Hypertension","Stage 2 Hypertension"))) -> Normal | H16: ='Raw Data'!I13 -> smoker | I16: ='Raw Data'!J13 -> low | K16: Non-Smoker | L16: =COUNTIFS(H5:H4159,"non-smoker") -> 2920 | M16: =L16/L6 -> 0.70276775
A17: =ROW()-4 -> 13 | B17: ='Raw Data'!B14 -> 20.643597 | C17: =IF(B17<18.5,"Underweight",IF(B17<=24.9,"Normal",IF(B17<=29.9,"Overweight","Obese"))) -> Normal | D17: ='Raw Data'!E14 -> 194.63319 | E17: =IF(D17<200,"Desirable",IF(D17<=239,"Borderline High","High")) -> Desirable | F17: ='Raw Data'!C14 -> 118.85959 | G17: =IF(F17<120,"Normal",IF(F17<=129,"Elevated",IF(F17<=139,"Stage 1 Hypertension","Stage 2 Hypertension"))) -> Normal | H17: ='Raw Data'!I14 -> non-smoker | I17: ='Raw Data'!J14 -> moderate
A18: =ROW()-4 -> 14 | B18: ='Raw Data'!B15 -> 25.730437 | C18: =IF(B18<18.5,"Underweight",IF(B18<=24.9,"Normal",IF(B18<=29.9,"Overweight","Obese"))) -> Overweight | D18: ='Raw Data'!E15 -> 218.84063 | E18: =IF(D18<200,"Desirable",IF(D18<=239,"Borderline High","High")) -> Borderline High | F18: ='Raw Data'!C15 -> 108.72682 | G18: =IF(F18<120,"Normal",IF(F18<=129,"Elevated",IF(F18<=139,"Stage 1 Hypertension","Stage 2 Hypertension"))) -> Normal | H18: ='Raw Data'!I15 -> non-smoker | I18: ='Raw Data'!J15 -> high | K18: Q3 — PHYSICAL ACTIVITY LEVEL
A19: =ROW()-4 -> 15 | B19: ='Raw Data'!B16 -> 26.051031 | C19: =IF(B19<18.5,"Underweight",IF(B19<=24.9,"Normal",IF(B19<=29.9,"Overweight","Obese"))) -> Overweight | D19: ='Raw Data'!E16 -> 205.00124 | E19: =IF(D19<200,"Desirable",IF(D19<=239,"Borderline High","High")) -> Borderline High | F19: ='Raw Data'!C16 -> 111.77577 | G19: =IF(F19<120,"Normal",IF(F19<=129,"Elevated",IF(F19<=139,"Stage 1 Hypertension","Stage 2 Hypertension"))) -> Normal | H19: ='Raw Data'!I16 -> non-smoker | I19: ='Raw Data'!J16 -> moderate | K19: Category | L19: Count | M19: Percent
A20: =ROW()-4 -> 16 | B20: ='Raw Data'!B17 -> 23.386377 | C20: =IF(B20<18.5,"Underweight",IF(B20<=24.9,"Normal",IF(B20<=29.9,"Overweight","Obese"))) -> Normal | D20: ='Raw Data'!E17 -> 187.36577 | E20: =IF(D20<200,"Desirable",IF(D20<=239,"Borderline High","High")) -> Desirable | F20: ='Raw Data'!C17 -> 114.42393 | G20: =IF(F20<120,"Normal",IF(F20<=129,"Elevated",IF(F20<=139,"Stage 1 Hypertension","Stage 2 Hypertension"))) -> Normal | H20: ='Raw Data'!I17 -> non-smoker | I20: ='Raw Data'!J17 -> low | K20: Low | L20: =COUNTIFS(I5:I4159,"low") -> 847 | M20: =L20/L6 -> 0.20385078
A21: =ROW()-4 -> 17 | B21: ='Raw Data'!B18 -> 20.210575 | C21: =IF(B21<18.5,"Underweight",IF(B21<=24.9,"Normal",IF(B21<=29.9,"Overweight","Obese"))) -> Normal | D21: ='Raw Data'!E18 -> 179.53943 | E21: =IF(D21<200,"Desirable",IF(D21<=239,"Borderline High","High")) -> Desirable | F21: ='Raw Data'!C18 -> 115.27341 | G21: =IF(F21<120,"Normal",IF(F21<=129,"Elevated",IF(F21<=139,"Stage 1 Hypertension","Stage 2 Hypertension"))) -> Normal | H21: ='Raw Data'!I18 -> smoker | I21: ='Raw Data'!J18 -> moderate | K21: Moderate | L21: =COUNTIFS(I5:I4159,"moderate") -> 2039 | M21: =L21/L6 -> 0.49073406
A22: =ROW()-4 -> 18 | B22: ='Raw Data'!B19 -> 24.217376 | C22: =IF(B22<18.5,"Underweight",IF(B22<=24.9,"Normal",IF(B22<=29.9,"Overweight","Obese"))) -> Normal | D22: ='Raw Data'!E19 -> 204.06703 | E22: =IF(D22<200,"Desirable",IF(D22<=239,"Borderline High","High")) -> Borderline High | F22: ='Raw Data'!C19 -> 104.81953 | G22: =IF(F22<120,"Normal",IF(F22<=129,"Elevated",IF(F22<=139,"Stage 1 Hypertension","Stage 2 Hypertension"))) -> Normal | H22: ='Raw Data'!I19 -> smoker | I22: ='Raw Data'!J19 -> low | K22: High | L22: =COUNTIFS(I5:I4159,"high") -> 1269 | M22: =L22/L6 -> 0.30541516
A23: =ROW()-4 -> 19 | B23: ='Raw Data'!B20 -> 24.632873 | C23: =IF(B23<18.5,"Underweight",IF(B23<=24.9,"Normal",IF(B23<=29.9,"Overweight","Obese"))) -> Normal | D23: ='Raw Data'!E20 -> 190.70725 | E23: =IF(D23<200,"Desirable",IF(D23<=239,"Borderline High","High")) -> Desirable | F23: ='Raw Data'!C20 -> 124.68439 | G23: =IF(F23<120,"Normal",IF(F23<=129,"Elevated",IF(F23<=139,"Stage 1 Hypertension","Stage 2 Hypertension"))) -> Elevated | H23: ='Raw Data'!I20 -> non-smoker | I23: ='Raw Data'!J20 -> low
A24: =ROW()-4 -> 20 | B24: ='Raw Data'!B21 -> 20.298439 | C24: =IF(B24<18.5,"Underweight",IF(B24<=24.9,"Normal",IF(B24<=29.9,"Overweight","Obese"))) -> Normal | D24: ='Raw Data'!E21 -> 185.57017 | E24: =IF(D24<200,"Desirable",IF(D24<=239,"Borderline High","High")) -> Desirable | F24: ='Raw Data'!C21 -> 127.71106 | G24: =IF(F24<120,"Normal",IF(F24<=129,"Elevated",IF(F24<=139,"Stage 1 Hypertension","Stage 2 Hypertension"))) -> Elevated | H24: ='Raw Data'!I21 -> non-smoker | I24: ='Raw Data'!J21 -> high | K24: Q4/Q7 — BMI CATEGORY DISTRIBUTION
A25: =ROW()-4 -> 21 | B25: ='Raw Data'!B22 -> 20.293209 | C25: =IF(B25<18.5,"Underweight",IF(B25<=24.9,"Normal",IF(B25<=29.9,"Overweight","Obese"))) -> Normal | D25: ='Raw Data'!E22 -> 185.1975 | E25: =IF(D25<200,"Desirable",IF(D25<=239,"Borderline High","High")) -> Desirable | F25: ='Raw Data'!C22 -> 104.03508 | G25: =IF(F25<120,"Normal",IF(F25<=129,"Elevated",IF(F25<=139,"Stage 1 Hypertension","Stage 2 Hypertension"))) -> Normal | H25: ='Raw Data'!I22 -> non-smoker | I25: ='Raw Data'!J22 -> low | K25: Category | L25: Count | M25: Percent
A26: =ROW()-4 -> 22 | B26: ='Raw Data'!B23 -> 16.540292 | C26: =IF(B26<18.5,"Underweight",IF(B26<=24.9,"Normal",IF(B26<=29.9,"Overweight","Obese"))) -> Underweight | D26: ='Raw Data'!E23 -> 178.48525 | E26: =IF(D26<200,"Desirable",IF(D26<=239,"Borderline High","High")) -> Desirable | F26: ='Raw Data'!C23 -> 103.86468 | G26: =IF(F26<120,"Normal",IF(F26<=129,"Elevated",IF(F26<=139,"Stage 1 Hypertension","Stage 2 Hypertension"))) -> Normal | H26: ='Raw Data'!I23 -> smoker | I26: ='Raw Data'!J23 -> moderate | K26: Underweight | L26: =COUNTIFS(C5:C4159,"Underweight") -> 165 | M26: =L26/L6 -> 0.039711191
A27: =ROW()-4 -> 23 | B27: ='Raw Data'!B24 -> 28.475366 | C27: =IF(B27<18.5,"Underweight",IF(B27<=24.9,"Normal",IF(B27<=29.9,"Overweight","Obese"))) -> Overweight | D27: ='Raw Data'!E24 -> 212.01352 | E27: =IF(D27<200,"Desirable",IF(D27<=239,"Borderline High","High")) -> Borderline High | F27: ='Raw Data'!C24 -> 114.74671 | G27: =IF(F27<120,"Normal",IF(F27<=129,"Elevated",IF(F27<=139,"Stage 1 Hypertension","Stage 2 Hypertension"))) -> Normal | H27: ='Raw Data'!I24 -> smoker | I27: ='Raw Data'!J24 -> low | K27: Normal | L27: =COUNTIFS(C5:C4159,"Normal") -> 1231 | M27: =L27/L6 -> 0.29626955
A28: =ROW()-4 -> 24 | B28: ='Raw Data'!B25 -> 31.890184 | C28: =IF(B28<18.5,"Underweight",IF(B28<=24.9,"Normal",IF(B28<=29.9,"Overweight","Obese"))) -> Obese | D28: ='Raw Data'!E25 -> 191.27561 | E28: =IF(D28<200,"Desirable",IF(D28<=239,"Borderline High","High")) -> Desirable | F28: ='Raw Data'!C25 -> 101.07251 | G28: =IF(F28<120,"Normal",IF(F28<=129,"Elevated",IF(F28<=139,"Stage 1 Hypertension","Stage 2 Hypertension"))) -> Normal | H28: ='Raw Data'!I25 -> smoker | I28: ='Raw Data'!J25 -> moderate | K28: Overweight | L28: =COUNTIFS(C5:C4159,"Overweight") -> 1568 | M28: =L28/L6 -> 0.37737665
A29: =ROW()-4 -> 25 | B29: ='Raw Data'!B26 -> 27.080511 | C29: =IF(B29<18.5,"Underweight",IF(B29<=24.9,"Normal",IF(B29<=29.9,"Overweight","Obese"))) -> Overweight | D29: ='Raw Data'!E26 -> 208.04638 | E29: =IF(D29<200,"Desirable",IF(D29<=239,"Borderline High","High")) -> Borderline High | F29: ='Raw Data'!C26 -> 110.49928 | G29: =IF(F29<120,"Normal",IF(F29<=129,"Elevated",IF(F29<=139,"Stage 1 Hypertension","Stage 2 Hypertension"))) -> Normal | H29: ='Raw Data'!I26 -> non-smoker | I29: ='Raw Data'!J26 -> high | K29: Obese | L29: =COUNTIFS(C5:C4159,"Obese") -> 1191 | M29: =L29/L6 -> 0.2866426
A30: =ROW()-4 -> 26 | B30: ='Raw Data'!B27 -> 24.978427 | C30: =IF(B30<18.5,"Underweight",IF(B30<=24.9,"Normal",IF(B30<=29.9,"Overweight","Obese"))) -> Overweight | D30: ='Raw Data'!E27 -> 218.65297 | E30: =IF(D30<200,"Desirable",IF(D30<=239,"Borderline High","High")) -> Borderline High | F30: ='Raw Data'!C27 -> 100.1188 | G30: =IF(F30<120,"Normal",IF(F30<=129,"Elevated",IF(F30<=139,"Stage 1 Hypertension","Stage 2 Hypertension"))) -> Normal | H30: ='Raw Data'!I27 -> smoker | I30: ='Raw Data'!J27 -> moderate | K30: Total | L30: =SUM(L26:L29) -> 4155 | M30: =SUM(M26:M29) -> 1
A31: =ROW()-4 -> 27 | B31: ='Raw Data'!B28 -> 20.049956 | C31: =IF(B31<18.5,"Underweight",IF(B31<=24.9,"Normal",IF(B31<=29.9,"Overweight","Obese"))) -> Normal | D31: ='Raw Data'!E28 -> 189.69765 | E31: =IF(D31<200,"Desirable",IF(D31<=239,"Borderline High","High")) -> Desirable | F31: ='Raw Data'!C28 -> 105.3986 | G31: =IF(F31<120,"Normal",IF(F31<=129,"Elevated",IF(F31<=139,"Stage 1 Hypertension","Stage 2 Hypertension"))) -> Normal | H31: ='Raw Data'!I28 -> non-smoker | I31: ='Raw Data'!J28 -> moderate
A32: =ROW()-4 -> 28 | B32: ='Raw Data'!B29 -> 15.975605 | C32: =IF(B32<18.5,"Underweight",IF(B32<=24.9,"Normal",IF(B32<=29.9,"Overweight","Obese"))) -> Underweight | D32: ='Raw Data'!E29 -> 213.34528 | E32: =IF(D32<200,"Desirable",IF(D32<=239,"Borderline High","High")) -> Borderline High | F32: ='Raw Data'!C29 -> 103.94328 | G32: =IF(F32<120,"Normal",IF(F32<=129,"Elevated",IF(F32<=139,"Stage 1 Hypertension","Stage 2 Hypertension"))) -> Normal | H32: ='Raw Data'!I29 -> non-smoker | I32: ='Raw Data'!J29 -> moderate | K32: Q5 — TOTAL CHOLESTEROL CLASSIFICATION
A33: =ROW()-4 -> 29 | B33: ='Raw Data'!B30 -> 26.835133 | C33: =IF(B33<18.5,"Underweight",IF(B33<=24.9,"Normal",IF(B33<=29.9,"Overweight","Obese"))) -> Overweight | D33: ='Raw Data'!E30 -> 195.30592 | E33: =IF(D33<200,"Desirable",IF(D33<=239,"Borderline High","High")) -> Desirable | F33: ='Raw Data'!C30 -> 113.58987 | G33: =IF(F33<120,"Normal",IF(F33<=129,"Elevated",IF(F33<=139,"Stage 1 Hypertension","Stage 2 Hypertension"))) -> Normal | H33: ='Raw Data'!I30 -> non-smoker | I33: ='Raw Data'!J30 -> low | K33: Category | L33: Count | M33: Percent
A34: =ROW()-4 -> 30 | B34: ='Raw Data'!B31 -> 30.078342 | C34: =IF(B34<18.5,"Underweight",IF(B34<=24.9,"Normal",IF(B34<=29.9,"Overweight","Obese"))) -> Obese | D34: ='Raw Data'!E31 -> 170.35572 | E34: =IF(D34<200,"Desirable",IF(D34<=239,"Borderline High","High")) -> Desirable | F34: ='Raw Data'!C31 -> 117.13588 | G34: =IF(F34<120,"Normal",IF(F34<=129,"Elevated",IF(F34<=139,"Stage 1 Hypertension","Stage 2 Hypertension"))) -> Normal | H34: ='Raw Data'!I31 -> non-smoker | I34: ='Raw Data'!J31 -> low | K34: Desirable | L34: =COUNTIFS(E5:E4159,"Desirable") -> 2767 | M34: =L34/L6 -> 0.66594465
A35: =ROW()-4 -> 31 | B35: ='Raw Data'!B32 -> 22.837958 | C35: =IF(B35<18.5,"Underweight",IF(B35<=24.9,"Normal",IF(B35<=29.9,"Overweight","Obese"))) -> Normal | D35: ='Raw Data'!E32 -> 213.56902 | E35: =IF(D35<200,"Desirable",IF(D35<=239,"Borderline High","High")) -> Borderline High | F35: ='Raw Data'!C32 -> 108.66225 | G35: =IF(F35<120,"Normal",IF(F35<=129,"Elevated",IF(F35<=139,"Stage 1 Hypertension","Stage 2 Hypertension"))) -> Normal | H35: ='Raw Data'!I32 -> non-smoker | I35: ='Raw Data'!J32 -> moderate | K35: Borderline High | L35: =COUNTIFS(E5:E4159,"Borderline High") -> 1377 | M35: =L35/L6 -> 0.33140794
A36: =ROW()-4 -> 32 | B36: ='Raw Data'!B33 -> 32.277049 | C36: =IF(B36<18.5,"Underweight",IF(B36<=24.9,"Normal",IF(B36<=29.9,"Overweight","Obese"))) -> Obese | D36: ='Raw Data'!E33 -> 183.77886 | E36: =IF(D36<200,"Desirable",IF(D36<=239,"Borderline High","High")) -> Desirable | F36: ='Raw Data'!C33 -> 120.70347 | G36: =IF(F36<120,"Normal",IF(F36<=129,"Elevated",IF(F36<=139,"Stage 1 Hypertension","Stage 2 Hypertension"))) -> Elevated | H36: ='Raw Data'!I33 -> smoker | I36: ='Raw Data'!J33 -> moderate | K36: High | L36: =COUNTIFS(E5:E4159,"High") -> 11 | M36: =L36/L6 -> 0.0026474128
A37: =ROW()-4 -> 33 | B37: ='Raw Data'!B34 -> 23.55556 | C37: =IF(B37<18.5,"Underweight",IF(B37<=24.9,"Normal",IF(B37<=29.9,"Overweight","Obese"))) -> Normal | D37: ='Raw Data'!E34 -> 189.06311 | E37: =IF(D37<200,"Desirable",IF(D37<=239,"Borderline High","High")) -> Desirable | F37: ='Raw Data'!C34 -> 98.792863 | G37: =IF(F37<120,"Normal",IF(F37<=129,"Elevated",IF(F37<=139,"Stage 1 Hypertension","Stage 2 Hypertension"))) -> Normal | H37: ='Raw Data'!I34 -> non-smoker | I37: ='Raw Data'!J34 -> moderate
A38: =ROW()-4 -> 34 | B38: ='Raw Data'!B35 -> 32.424991 | C38: =IF(B38<18.5,"Underweight",IF(B38<=24.9,"Normal",IF(B38<=29.9,"Overweight","Obese"))) -> Obese | D38: ='Raw Data'!E35 -> 175.07758 | E38: =IF(D38<200,"Desirable",IF(D38<=239,"Borderline High","High")) -> Desirable | F38: ='Raw Data'!C35 -> 104.41686 | G38: =IF(F38<120,"Normal",IF(F38<=129,"Elevated",IF(F38<=139,"Stage 1 Hypertension","Stage 2 Hypertension"))) -> Normal | H38: ='Raw Data'!I35 -> non-smoker | I38: ='Raw Data'!J35 -> high | K38: Q6 — SYSTOLIC BLOOD PRESSURE CLASSIFICATION
A39: =ROW()-4 -> 35 | B39: ='Raw Data'!B36 -> 23.09602 | C39: =IF(B39<18.5,"Underweight",IF(B39<=24.9,"Normal",IF(B39<=29.9,"Overweight","Obese"))) -> Normal | D39: ='Raw Data'!E36 -> 176.29877 | E39: =IF(D39<200,"Desirable",IF(D39<=239,"Borderline High","High")) -> Desirable | F39: ='Raw Data'!C36 -> 98.006627 | G39: =IF(F39<120,"Normal",IF(F39<=129,"Elevated",IF(F39<=139,"Stage 1 Hypertension","Stage 2 Hypertension"))) -> Normal | H39: ='Raw Data'!I36 -> non-smoker | I39: ='Raw Data'!J36 -> moderate | K39: Category | L39: Count | M39: Percent
A40: =ROW()-4 -> 36 | B40: ='Raw Data'!B37 -> 13.68534 | C40: =IF(B40<18.5,"Underweight",IF(B40<=24.9,"Normal",IF(B40<=29.9,"Overweight","Obese"))) -> Underweight | D40: ='Raw Data'!E37 -> 170.50582 | E40: =IF(D40<200,"Desirable",IF(D40<=239,"Borderline High","High")) -> Desirable | F40: ='Raw Data'!C37 -> 117.26973 | G40: =IF(F40<120,"Normal",IF(F40<=129,"Elevated",IF(F40<=139,"Stage 1 Hypertension","Stage 2 Hypertension"))) -> Normal | H40: ='Raw Data'!I37 -> non-smoker | I40: ='Raw Data'!J37 -> moderate | K40: Normal | L40: =COUNTIFS(G5:G4159,"Normal") -> 3563 | M40: =L40/L6 -> 0.85752106
A41: =ROW()-4 -> 37 | B41: ='Raw Data'!B38 -> 30.131779 | C41: =IF(B41<18.5,"Underweight",IF(B41<=24.9,"Normal",IF(B41<=29.9,"Overweight","Obese"))) -> Obese | D41: ='Raw Data'!E38 -> 185.0021 | E41: =IF(D41<200,"Desirable",IF(D41<=239,"Borderline High","High")) -> Desirable | F41: ='Raw Data'!C38 -> 106.39175 | G41: =IF(F41<120,"Normal",IF(F41<=129,"Elevated",IF(F41<=139,"Stage 1 Hypertension","Stage 2 Hypertension"))) -> Normal | H41: ='Raw Data'!I38 -> smoker | I41: ='Raw Data'!J38 -> moderate | K41: Elevated | L41: =COUNTIFS(G5:G4159,"Elevated") -> 489 | M41: =L41/L6 -> 0.11768953
...

Sheet Raw Data
A1: Age | B1: BMI | C1: Systolic_BP | D1: Diastolic_BP | E1: Total_Cholesterol | F1: HDL_Cholesterol | G1: LDL_Cholesterol | H1: Triglycerides | I1: Smoking_Status | J1: Physical_Activity_Level | K1: BP_Risk_Category | L1: Age_Group | M1: BMI_Category | N1: Cholesterol_Ratio | O1: Pulse_Pressure | P1: BMI_Age_Interaction | Q1: Cholesterol_Category | R1: Systolic_BP_Category | S1: Health_Risk_Score (Analytical Index) | T1: Risk_Tier (Analytical) | W1: HOME | X1: HEALTH OVERVIEW | Y1: INSIGHTS | Z1: BUSINESS QUESTIONS | AA1: DATA DICTIONARY | AB1: ANALYSIS
A2: 69 | B2: 20.716059 | C2: 107.14844 | D2: 58.251503 | E2: 168.91851 | F2: 38.417674 | G2: 183.83506 | H2: 243.34153 | I2: non-smoker | J2: moderate | K2: Normal | L2: 60-69 | M2: Normal | N2: 4.3968958 | O2: 48.896935 | P2: 1429.408 | Q2: =IF(E2<200,"Desirable",IF(E2<240,"Borderline High","High")) -> Desirable | R2: =IF(C2<120,"Normal",IF(C2<130,"Elevated",IF(C2<140,"High / Stage 1","High / Stage 2"))) -> Normal | S2: =(IF(M2="Obese",3,IF(M2="Overweight",2,IF(M2="Underweight",1,0))))+(IF(R2="High / Stage 2",3,IF(R2="High / Stage 1",2,IF(R2="Elevated",1,0))))+IF(I2="smoker",2,0)+IF(F2<40,1,0) -> 1 | T2: =IF(S2<=2,"Low",IF(S2<=5,"Moderate","High")) -> Low
A3: 32 | B3: 26.720231 | C3: 102.94833 | D3: 86.641598 | E3: 203.91201 | F3: 39.611571 | G3: 209.0846 | H3: 266.37542 | I3: smoker | J3: high | K3: Elevated / High Risk | L3: 30-39 | M3: Overweight | N3: 5.1477891 | O3: 16.306729 | P3: 855.04738 | Q3: =IF(E3<200,"Desirable",IF(E3<240,"Borderline High","High")) -> Borderline High | R3: =IF(C3<120,"Normal",IF(C3<130,"Elevated",IF(C3<140,"High / Stage 1","High / Stage 2"))) -> Normal | S3: =(IF(M3="Obese",3,IF(M3="Overweight",2,IF(M3="Underweight",1,0))))+(IF(R3="High / Stage 2",3,IF(R3="High / Stage 1",2,IF(R3="Elevated",1,0))))+IF(I3="smoker",2,0)+IF(F3<40,1,0) -> 5 | T3: =IF(S3<=2,"Low",IF(S3<=5,"Moderate","High")) -> Moderate
A4: 89 | B4: 25.971636 | C4: 116.32703 | D4: 90.282522 | E4: 213.56482 | F4: 39.406223 | G4: 245.88483 | H4: 256.97453 | I4: non-smoker | J4: moderate | K4: Elevated / High Risk | L4: 70+ | M4: Overweight | N4: 5.4195709 | O4: 26.044511 | P4: 2311.4756 | Q4: =IF(E4<200,"Desirable",IF(E4<240,"Borderline High","High")) -> Borderline High | R4: =IF(C4<120,"Normal",IF(C4<130,"Elevated",IF(C4<140,"High / Stage 1","High / Stage 2"))) -> Normal | S4: =(IF(M4="Obese",3,IF(M4="Overweight",2,IF(M4="Underweight",1,0))))+(IF(R4="High / Stage 2",3,IF(R4="High / Stage 1",2,IF(R4="Elevated",1,0))))+IF(I4="smoker",2,0)+IF(F4<40,1,0) -> 3 | T4: =IF(S4<=2,"Low",IF(S4<=5,"Moderate","High")) -> Moderate
A5: 78 | B5: 29.580788 | C5: 104.2738 | D5: 85.582392 | E5: 204.30191 | F5: 33.026881 | G5: 207.49365 | H5: 257.71782 | I5: non-smoker | J5: moderate | K5: Elevated / High Risk | L5: 70+ | M5: Overweight | N5: 6.1859281 | O5: 18.691408 | P5: 2307.3015 | Q5: =IF(E5<200,"Desirable",IF(E5<240,"Borderline High","High")) -> Borderline High | R5: =IF(C5<120,"Normal",IF(C5<130,"Elevated",IF(C5<140,"High / Stage 1","High / Stage 2"))) -> Normal | S5: =(IF(M5="Obese",3,IF(M5="Overweight",2,IF(M5="Underweight",1,0))))+(IF(R5="High / Stage 2",3,IF(R5="High / Stage 1",2,IF(R5="Elevated",1,0))))+IF(I5="smoker",2,0)+IF(F5<40,1,0) -> 3 | T5: =IF(S5<=2,"Low",IF(S5<=5,"Moderate","High")) -> Moderate
A6: 38 | B6: 28.35313 | C6: 104.05258 | D6: 81.32627 | E6: 195.76714 | F6: 34.558842 | G6: 213.82674 | H6: 246.5134 | I6: non-smoker | J6: moderate | K6: Elevated / High Risk | L6: 30-39 | M6: Overweight | N6: 5.6647484 | O6: 22.726314 | P6: 1077.4189 | Q6: =IF(E6<200,"Desirable",IF(E6<240,"Borderline High","High")) -> Desirable | R6: =IF(C6<120,"Normal",IF(C6<130,"Elevated",IF(C6<140,"High / Stage 1","High / Stage 2"))) -> Normal | S6: =(IF(M6="Obese",3,IF(M6="Overweight",2,IF(M6="Underweight",1,0))))+(IF(R6="High / Stage 2",3,IF(R6="High / Stage 1",2,IF(R6="Elevated",1,0))))+IF(I6="smoker",2,0)+IF(F6<40,1,0) -> 3 | T6: =IF(S6<=2,"Low",IF(S6<=5,"Moderate","High")) -> Moderate
A7: 41 | B7: 27.996372 | C7: 108.0406 | D7: 76.962398 | E7: 209.92055 | F7: 30.076118 | G7: 242.84323 | H7: 247.81822 | I7: smoker | J7: moderate | K7: Normal | L7: 40-49 | M7: Overweight | N7: 6.9796424 | O7: 31.078204 | P7: 1147.8513 | Q7: =IF(E7<200,"Desirable",IF(E7<240,"Borderline High","High")) -> Borderline High | R7: =IF(C7<120,"Normal",IF(C7<130,"Elevated",IF(C7<140,"High / Stage 1","High / Stage 2"))) -> Normal | S7: =(IF(M7="Obese",3,IF(M7="Overweight",2,IF(M7="Underweight",1,0))))+(IF(R7="High / Stage 2",3,IF(R7="High / Stage 1",2,IF(R7="Elevated",1,0))))+IF(I7="smoker",2,0)+IF(F7<40,1,0) -> 5 | T7: =IF(S7<=2,"Low",IF(S7<=5,"Moderate","High")) -> Moderate
A8: 20 | B8: 31.834551 | C8: 111.37421 | D8: 84.416439 | E8: 190.26447 | F8: 30.704549 | G8: 219.37064 | H8: 247.03536 | I8: non-smoker | J8: low | K8: Elevated / High Risk | L8: 18-29 | M8: Obese | N8: 6.1966215 | O8: 26.957774 | P8: 636.69102 | Q8: =IF(E8<200,"Desirable",IF(E8<240,"Borderline High","High")) -> Desirable | R8: =IF(C8<120,"Normal",IF(C8<130,"Elevated",IF(C8<140,"High / Stage 1","High / Stage 2"))) -> Normal | S8: =(IF(M8="Obese",3,IF(M8="Overweight",2,IF(M8="Underweight",1,0))))+(IF(R8="High / Stage 2",3,IF(R8="High / Stage 1",2,IF(R8="Elevated",1,0))))+IF(I8="smoker",2,0)+IF(F8<40,1,0) -> 4 | T8: =IF(S8<=2,"Low",IF(S8<=5,"Moderate","High")) -> Moderate
A9: 39 | B9: 24.850209 | C9: 101.27835 | D9: 79.690007 | E9: 173.17795 | F9: 40.846727 | G9: 227.86761 | H9: 233.36564 | I9: smoker | J9: high | K9: Normal | L9: 30-39 | M9: Normal | N9: 4.2397021 | O9: 21.588341 | P9: 969.15814 | Q9: =IF(E9<200,"Desirable",IF(E9<240,"Borderline High","High")) -> Desirable | R9: =IF(C9<120,"Normal",IF(C9<130,"Elevated",IF(C9<140,"High / Stage 1","High / Stage 2"))) -> Normal | S9: =(IF(M9="Obese",3,IF(M9="Overweight",2,IF(M9="Underweight",1,0))))+(IF(R9="High / Stage 2",3,IF(R9="High / Stage 1",2,IF(R9="Elevated",1,0))))+IF(I9="smoker",2,0)+IF(F9<40,1,0) -> 2 | T9: =IF(S9<=2,"Low",IF(S9<=5,"Moderate","High")) -> Low
A10: 70 | B10: 29.693623 | C10: 103.89739 | D10: 90.322002 | E10: 207.03529 | F10: 41.726528 | G10: 225.14782 | H10: 243.55059 | I10: non-smoker | J10: high | K10: Elevated / High Risk | L10: 70+ | M10: Overweight | N10: 4.9617185 | O10: 13.575386 | P10: 2078.5536 | Q10: =IF(E10<200,"Desirable",IF(E10<240,"Borderline High","High")) -> Borderline High | R10: =IF(C10<120,"Normal",IF(C10<130,"Elevated",IF(C10<140,"High / Stage 1","High / Stage 2"))) -> Normal | S10: =(IF(M10="Obese",3,IF(M10="Overweight",2,IF(M10="Underweight",1,0))))+(IF(R10="High / Stage 2",3,IF(R10="High / Stage 1",2,IF(R10="Elevated",1,0))))+IF(I10="smoker",2,0)+IF(F10<40,1,0) -> 2 | T10: =IF(S10<=2,"Low",IF(S10<=5,"Moderate","High")) -> Low
A11: 19 | B11: 28.404333 | C11: 94.798266 | D11: 81.773501 | E11: 212.837 | F11: 37.489546 | G11: 219.57031 | H11: 271.25612 | I11: non-smoker | J11: high | K11: Elevated / High Risk | L11: 18-29 | M11: Overweight | N11: 5.6772359 | O11: 13.024766 | P11: 539.68232 | Q11: =IF(E11<200,"Desirable",IF(E11<240,"Borderline High","High")) -> Borderline High | R11: =IF(C11<120,"Normal",IF(C11<130,"Elevated",IF(C11<140,"High / Stage 1","High / Stage 2"))) -> Normal | S11: =(IF(M11="Obese",3,IF(M11="Overweight",2,IF(M11="Underweight",1,0))))+(IF(R11="High / Stage 2",3,IF(R11="High / Stage 1",2,IF(R11="Elevated",1,0))))+IF(I11="smoker",2,0)+IF(F11<40,1,0) -> 3 | T11: =IF(S11<=2,"Low",IF(S11<=5,"Moderate","High")) -> Moderate
A12: 47 | B12: 27.569727 | C12: 108.97669 | D12: 75.17546 | E12: 174.18979 | F12: 35.207356 | G12: 205.97011 | H12: 273.61071 | I12: smoker | J12: high | K12: Normal | L12: 40-49 | M12: Overweight | N12: 4.9475397 | O12: 33.801228 | P12: 1295.7772 | Q12: =IF(E12<200,"Desirable",IF(E12<240,"Borderline High","High")) -> Desirable | R12: =IF(C12<120,"Normal",IF(C12<130,"Elevated",IF(C12<140,"High / Stage 1","High / Stage 2"))) -> Normal | S12: =(IF(M12="Obese",3,IF(M12="Overweight",2,IF(M12="Underweight",1,0))))+(IF(R12="High / Stage 2",3,IF(R12="High / Stage 1",2,IF(R12="Elevated",1,0))))+IF(I12="smoker",2,0)+IF(F12<40,1,0) -> 5 | T12: =IF(S12<=2,"Low",IF(S12<=5,"Moderate","High")) -> Moderate
A13: 55 | B13: 26.671476 | C13: 104.67322 | D13: 84.288149 | E13: 176.70644 | F13: 39.171277 | G13: 199.04885 | H13: 268.17643 | I13: smoker | J13: low | K13: Elevated / High Risk | L13: 50-59 | M13: Overweight | N13: 4.5111227 | O13: 20.385073 | P13: 1466.9312 | Q13: =IF(E13<200,"Desirable",IF(E13<240,"Borderline High","High")) -> Desirable | R13: =IF(C13<120,"Normal",IF(C13<130,"Elevated",IF(C13<140,"High / Stage 1","High / Stage 2"))) -> Normal | S13: =(IF(M13="Obese",3,IF(M13="Overweight",2,IF(M13="Underweight",1,0))))+(IF(R13="High / Stage 2",3,IF(R13="High / Stage 1",2,IF(R13="Elevated",1,0))))+IF(I13="smoker",2,0)+IF(F13<40,1,0) -> 5 | T13: =IF(S13<=2,"Low",IF(S13<=5,"Moderate","High")) -> Moderate
... A4156: 47 | B4156: 21.285659 | C4156: 95.051643 | D4156: 76.265616 | E4156: 154.85753 | F4156: 41.775687 | G4156: 202.83243 | H4156: 232.09018 | I4156: non-smoker | J4156: moderate | K4156: Normal | L4156: 40-49 | M4156: Normal | N4156: 3.7068817 | O4156: 18.786027 | P4156: 1000.426 | Q4156: =IF(E4156<200,"Desirable",IF(E4156<240,"Borderline High","High")) -> Desirable | R4156: =IF(C4156<120,"Normal",IF(C4156<130,"Elevated",IF(C4156<140,"High / Stage 1","High / Stage 2"))) -> Normal | S4156: =(IF(M4156="Obese",3,IF(M4156="Overweight",2,IF(M4156="Underweight",1,0))))+(IF(R4156="High / Stage 2",3,IF(R4156="High / Stage 1",2,IF(R4156="Elevated",1,0))))+IF(I4156="smoker",2,0)+IF(F4156<40,1,0) -> 0 | T4156: =IF(S4156<=2,"Low",IF(S4156<=5,"Moderate","High")) -> Low

Sheet Lists
A1: Smoking Status | B1: Physical Activity Level | C1: BMI Category | D1: Cholesterol Category | E1: Systolic BP Category | F1: Age Group
A2: (All) | B2: (All) | C2: (All) | D2: (All) | E2: (All) | F2: (All)
A3: smoker | B3: low | C3: Underweight | D3: Desirable | E3: Normal | F3: 18-29
A4: non-smoker | B4: moderate | C4: Normal | D4: Borderline High | E4: Elevated | F4: 30-39
B5: high | C5: Overweight | D5: High | E5: High / Stage 1 | F5: 40-49
C6: Obese | E6: High / Stage 2 | F6: 50-59
F7: 60-69
F8: 70+

Sheet Dashboard Data
A1: Smoking Status
A2: Category | B2: Value
A3: Smoker | B3: 1235
A4: Non-Smoker | B4: 2920
A7: Physical Activity Level
A8: Category | B8: Value
A9: Low | B9: 847
A10: Moderate | B10: 2039
A11: High | B11: 1269
A14: BMI Category
A15: Category | B15: Value
A16: Underweight | B16: 165
A17: Normal | B17: 1231
A18: Overweight | B18: 1568
A19: Obese | B19: 1191
A22: Cholesterol Category
A23: Category | B23: Value
A24: Desirable (<200) | B24: 2767
A25: Borderline High (200-239) | B25: 1377
A26: High (≥240) | B26: 11
A29: Systolic BP Category
A30: Category | B30: Value
A31: Normal (<120) | B31: 3562
A32: Elevated (120-129) | B32: 512
A33: High / Stage 1 (130-139) | B33: 76
A34: High / Stage 2 (≥140) | B34: 5
A37: Age Group
A38: Category | B38: Value
A39: 18-29 | B39: 673
A40: 30-39 | B40: 602
A41: 40-49 | B41: 564
A42: 50-59 | B42: 626
A43: 60-69 | B43: 558
A44: 70+ | B44: 1132
A47: Average BMI by Activity
A48: Category | B48: Value
A49: Low | B49: 27.051044
A50: Moderate | B50: 27.029063
A51: High | B51: 27.003708
A54: Average BMI by Smoking
...

Sheet Insights
A1: KEY INSIGHTS & RELATIONSHIP ANALYSIS
A3: Automated population signals + BMI / systolic BP relationship analysis
A5: AUTOMATED KEY INSIGHTS
A6: Population | E6: =COUNTA('Raw Data'!A2:A4156) -> 4155 | I6: records
A7: Average BMI | E7: =AVERAGE('Raw Data'!B2:B4156) -> 27.0258 | I7: kg/m²
A8: Average SBP | E8: =AVERAGE('Raw Data'!C2:C4156) -> 109.0148 | I8: mmHg
A9: Smoking Rate | E9: =COUNTIF('Raw Data'!I2:I4156,"Smoker")/4155 -> 0.29723225 | I9: %
A10: Overweight + Obese | E10: =COUNTIF('Raw Data'!B2:B4156,">=25")/4155 -> 0.65776173 | I10: %
A13: CORRELATION ANALYSIS
A14: BMI vs Systolic BP: descriptive relationship only; association does not establish causation.
A17: HOME | B17: HEALTH OVERVIEW | C17: RISK SUMMARY | D17: INSIGHTS | E17: DATA QUALITY | F17: ANALYSIS

Sheet Correlation Data
A1: BMI | B1: Systolic BP
A2: ='Raw Data'!B2 -> 20.716059 | B2: ='Raw Data'!C2 -> 107.14844
A3: ='Raw Data'!B3 -> 26.720231 | B3: ='Raw Data'!C3 -> 102.94833
A4: ='Raw Data'!B4 -> 25.971636 | B4: ='Raw Data'!C4 -> 116.32703
A5: ='Raw Data'!B5 -> 29.580788 | B5: ='Raw Data'!C5 -> 104.2738
A6: ='Raw Data'!B6 -> 28.35313 | B6: ='Raw Data'!C6 -> 104.05258
A7: ='Raw Data'!B7 -> 27.996372 | B7: ='Raw Data'!C7 -> 108.0406
A8: ='Raw Data'!B8 -> 31.834551 | B8: ='Raw Data'!C8 -> 111.37421
A9: ='Raw Data'!B9 -> 24.850209 | B9: ='Raw Data'!C9 -> 101.27835
A10: ='Raw Data'!B10 -> 29.693623 | B10: ='Raw Data'!C10 -> 103.89739
A11: ='Raw Data'!B11 -> 28.404333 | B11: ='Raw Data'!C11 -> 94.798266
A12: ='Raw Data'!B12 -> 27.569727 | B12: ='Raw Data'!C12 -> 108.97669
A13: ='Raw Data'!B13 -> 26.671476 | B13: ='Raw Data'!C13 -> 104.67322
... A1001: ='Raw Data'!B1001 -> 25.922542 | B1001: ='Raw Data'!C1001 -> 107.4956

Sheet Data Quality
A1: DATA QUALITY & CONTROL CENTER
A3: Completeness and basic validation checks
A5: QUALITY KPIs
A6: Total Records | B6: =COUNTA('Raw Data'!A2:A4156) -> 4155
A7: Total Fields | B7: =COUNTA('Raw Data'!1:1) -> 26
A8: Rows With Any Blank | B8: =SUMPRODUCT(--(MMULT(--('Raw Data'!A2:T4156=""),TRANSPOSE(COLUMN('Raw Data'!A1:T1)^0))>0)) -> #VALUE!
A11: FIELD COMPLETENESS
A12: Field | B12: Non-Blank | C12: Completeness | D12: Status
A13: Age | B13: =COUNTA('Raw Data'!A2:A4156) -> 4155 | C13: =B13/4155 -> 1 | D13: =IF(C13=1,"GOOD",IF(C13>=0.95,"REVIEW","ACTION")) -> GOOD
A14: BMI | B14: =COUNTA('Raw Data'!B2:B4156) -> 4155 | C14: =B14/4155 -> 1 | D14: =IF(C14=1,"GOOD",IF(C14>=0.95,"REVIEW","ACTION")) -> GOOD
A15: Systolic_BP | B15: =COUNTA('Raw Data'!C2:C4156) -> 4155 | C15: =B15/4155 -> 1 | D15: =IF(C15=1,"GOOD",IF(C15>=0.95,"REVIEW","ACTION")) -> GOOD
A16: Diastolic_BP | B16: =COUNTA('Raw Data'!D2:D4156) -> 4155 | C16: =B16/4155 -> 1 | D16: =IF(C16=1,"GOOD",IF(C16>=0.95,"REVIEW","ACTION")) -> GOOD
A17: Total_Cholesterol | B17: =COUNTA('Raw Data'!E2:E4156) -> 4155 | C17: =B17/4155 -> 1 | D17: =IF(C17=1,"GOOD",IF(C17>=0.95,"REVIEW","ACTION")) -> GOOD
A18: HDL_Cholesterol | B18: =COUNTA('Raw Data'!F2:F4156) -> 4155 | C18: =B18/4155 -> 1 | D18: =IF(C18=1,"GOOD",IF(C18>=0.95,"REVIEW","ACTION")) -> GOOD
A19: LDL_Cholesterol | B19: =COUNTA('Raw Data'!G2:G4156) -> 4155 | C19: =B19/4155 -> 1 | D19: =IF(C19=1,"GOOD",IF(C19>=0.95,"REVIEW","ACTION")) -> GOOD
A20: Triglycerides | B20: =COUNTA('Raw Data'!H2:H4156) -> 4155 | C20: =B20/4155 -> 1 | D20: =IF(C20=1,"GOOD",IF(C20>=0.95,"REVIEW","ACTION")) -> GOOD
A21: Smoking_Status | B21: =COUNTA('Raw Data'!I2:I4156) -> 4155 | C21: =B21/4155 -> 1 | D21: =IF(C21=1,"GOOD",IF(C21>=0.95,"REVIEW","ACTION")) -> GOOD
A22: Physical_Activity_Level | B22: =COUNTA('Raw Data'!J2:J4156) -> 4155 | C22: =B22/4155 -> 1 | D22: =IF(C22=1,"GOOD",IF(C22>=0.95,"REVIEW","ACTION")) -> GOOD
A23: BP_Risk_Category | B23: =COUNTA('Raw Data'!K2:K4156) -> 4155 | C23: =B23/4155 -> 1 | D23: =IF(C23=1,"GOOD",IF(C23>=0.95,"REVIEW","ACTION")) -> GOOD
A24: Age_Group | B24: =COUNTA('Raw Data'!L2:L4156) -> 4155 | C24: =B24/4155 -> 1 | D24: =IF(C24=1,"GOOD",IF(C24>=0.95,"REVIEW","ACTION")) -> GOOD
A25: BMI_Category | B25: =COUNTA('Raw Data'!M2:M4156) -> 4155 | C25: =B25/4155 -> 1 | D25: =IF(C25=1,"GOOD",IF(C25>=0.95,"REVIEW","ACTION")) -> GOOD
A26: Cholesterol_Ratio | B26: =COUNTA('Raw Data'!N2:N4156) -> 4155 | C26: =B26/4155 -> 1 | D26: =IF(C26=1,"GOOD",IF(C26>=0.95,"REVIEW","ACTION")) -> GOOD
A27: Pulse_Pressure | B27: =COUNTA('Raw Data'!O2:O4156) -> 4155 | C27: =B27/4155 -> 1 | D27: =IF(C27=1,"GOOD",IF(C27>=0.95,"REVIEW","ACTION")) -> GOOD
A28: BMI_Age_Interaction | B28: =COUNTA('Raw Data'!P2:P4156) -> 4155 | C28: =B28/4155 -> 1 | D28: =IF(C28=1,"GOOD",IF(C28>=0.95,"REVIEW","ACTION")) -> GOOD
A29: Cholesterol_Category | B29: =COUNTA('Raw Data'!Q2:Q4156) -> 4155 | C29: =B29/4155 -> 1 | D29: =IF(C29=1,"GOOD",IF(C29>=0.95,"REVIEW","ACTION")) -> GOOD
A30: Systolic_BP_Category | B30: =COUNTA('Raw Data'!R2:R4156) -> 4155 | C30: =B30/4155 -> 1 | D30: =IF(C30=1,"GOOD",IF(C30>=0.95,"REVIEW","ACTION")) -> GOOD
A31: Health_Risk_Score (Analytical Index) | B31: =COUNTA('Raw Data'!S2:S4156) -> 4155 | C31: =B31/4155 -> 1 | D31: =IF(C31=1,"GOOD",IF(C31>=0.95,"REVIEW","ACTION")) -> GOOD
A32: Risk_Tier (Analytical) | B32: =COUNTA('Raw Data'!T2:T4156) -> 4155 | C32: =B32/4155 -> 1 | D32: =IF(C32=1,"GOOD",IF(C32>=0.95,"REVIEW","ACTION")) -> GOOD
A34: HOME | B34: HEALTH OVERVIEW | C34: RISK SUMMARY | D34: INSIGHTS | E34: DATA QUALITY | F34: ANALYSIS
